Workbook

Sheet ИСХОД. ДАННЫЕ
A1: DR_Dat | B1: DR_Tim | C1: DR_NChk | D1: DR_NDoc | E1: DR_Apt | F1: DR_Kkm | G1: DR_TDoc | H1: DR_TPay | I1: DR_CDrugs | J1: DR_NDrugs | K1: DR_Suppl | L1: DR_Prod | M1: DR_Kol | N1: DR_Czak(закуп цена) | O1: DR_Croz (розничная цена) | P1: DR_Sdisc (сумма скидки) | Q1: DR_CDisc | R1: DR_BCDisc | S1: DR_TabEmpl | T1: DR_VZak | U1: DR_Pos
A2: 44774 | B2: 0.33770833 | C2: 1272 | D2: 13002561 | E2: 13 | F2: 22589 | G2: Розничная реализация | H2: 18 | I2: 144734 | J2: ГАСТАЛ №12 ТАБ. Д/РАСС. | K2: Пульс | L2: TEVA Pharvaceutical Industries Ltd | M2: 1 | N2: 196.71 | O2: 270 | P2: 0 | Q2: NULL | R2: NULL | S2: 29 | T2: 1 | U2: 1 | W2: 1. месячная оборачиваемость
A3: 44774 | B3: 0.36033565 | C3: 1273 | D3: 13002561 | E3: 13 | F3: 22589 | G3: Розничная реализация | H3: 15 | I3: 69661 | J3: ТОБРОПТ 0,3% 5МЛ. №1 ГЛ.КАПЛИ ФЛ./КАП. /РОМФАРМ/ | K3: Пульс | L3: РОМФАРМ КОМПАНИ ( ROMPHARM ) | M3: 1 | N3: 106.21 | O3: 127 | P3: 6 | Q3: 9 | R3: 200010004357 | S3: 29 | T3: 1 | U3: 1
A4: 44774 | B4: 0.37196759 | C4: 1274 | D4: 13002561 | E4: 13 | F4: 22589 | G4: Розничная реализация | H4: 18 | I4: 190635 | J4: ЭЛИКВИС 5МГ. №60 ТАБ. П/П/О /ПФАЙЗЕР/БРИСТОЛ-МАЙЕРС/ | K4: ГРАНД КАПИТАЛ СМОЛЕНСК ООО ФК | L4: Пфайзер | M4: 1 | N4: 2320.99 | O4: 2563 | P4: 76 | Q4: 9 | R4: 200010018491 | S4: 29 | T4: 1 | U4: 1 | W4: Обратите внимание, у вас появилась новая метрика для анализа - месячная оборачиваемость. Считайте ее как среднедневное количество продаж умноженное на 30 дней. Эта метрика показывает, сколько штук товара в месяц мы потенциально можем продать.
A5: 44774 | B5: 0.37546296 | C5: 1275 | D5: 13002561 | E5: 13 | F5: 22589 | G5: Розничная реализация | H5: 18 | I5: 276370 | J5: АРБИДОЛ МАКСИМУМ 200МГ. №10 КАПС. /ОТИСИФАРМ/ФАРМСТАНДАРТ/ | K5: Пульс | L5: ОТИСИФАРМ ПАО | M5: 1 | N5: 445.39 | O5: 541 | P5: 0 | Q5: NULL | R5: NULL | S5: 29 | T5: 1 | U5: 1
A6: 44774 | B6: 0.37783565 | C6: 1276 | D6: 13002561 | E6: 13 | F6: 22589 | G6: Розничная реализация | H6: 15 | I6: 2303 | J6: ЭНАМ 2,5МГ. №20 ТАБ. /Д-Р РЕДДИ/ | K6: Протек | L6: Д-р Редди с Лабораторис Лтд / Dr.REDDY's | M6: 1 | N6: 18.04 | O6: 22 | P6: 1 | Q6: 9 | R6: 200010000734 | S6: 29 | T6: 1 | U6: 5
A7: 44774 | B7: 0.37783565 | C7: 1276 | D7: 13002561 | E7: 13 | F7: 22589 | G7: Розничная реализация | H7: 15 | I7: 2303 | J7: ЭНАМ 2,5МГ. №20 ТАБ. /Д-Р РЕДДИ/ | K7: Протек | L7: Д-р Редди с Лабораторис Лтд / Dr.REDDY's | M7: 1 | N7: 18.04 | O7: 22 | P7: 1 | Q7: 9 | R7: 200010000734 | S7: 29 | T7: 1 | U7: 6
A8: 44774 | B8: 0.37783565 | C8: 1276 | D8: 13002561 | E8: 13 | F8: 22589 | G8: Розничная реализация | H8: 15 | I8: 338588 | J8: КЛОПИДОГРЕЛ-СЗ 75МГ. №28 ТАБ. П/П/О /СЕВЕРНАЯ ЗВЕЗДА/ | K8: Пульс | L8: Северная Звезда | M8: 1 | N8: 383.7 | O8: 475 | P8: 23 | Q8: 9 | R8: 200010000734 | S8: 29 | T8: 1 | U8: 3
A9: 44774 | B9: 0.37783565 | C9: 1276 | D9: 13002561 | E9: 13 | F9: 22589 | G9: Розничная реализация | H9: 15 | I9: 397616 | J9: КО-ВАМЛОСЕТ 5МГ.+160МГ.+12,5МГ. №30 ТАБ. П/П/О | K9: Протек | L9: КРКА-Рус ООО (KRKA ) | M9: 1 | N9: 536.82 | O9: 693 | P9: 48 | Q9: 9 | R9: 200010000734 | S9: 29 | T9: 1 | U9: 4
A10: 44774 | B10: 0.37783565 | C10: 1276 | D10: 13002561 | E10: 13 | F10: 22589 | G10: Розничная реализация | H10: 15 | I10: 338492 | J10: АТОРВАСТАТИН-СЗ 20МГ. №60 ТАБ. П/П/О /СЕВЕРНАЯ ЗВЕЗДА/ | K10: Протек | L10: Северная Звезда | M10: 1 | N10: 334.29 | O10: 418 | P10: 20 | Q10: 9 | R10: 200010000734 | S10: 29 | T10: 1 | U10: 1
A11: 44774 | B11: 0.37783565 | C11: 1276 | D11: 13002561 | E11: 13 | F11: 22589 | G11: Розничная реализация | H11: 15 | I11: 338479 | J11: АТОРВАСТАТИН-СЗ 40МГ. №30 ТАБ. П/П/О /СЕВЕРНАЯ ЗВЕЗДА/ | K11: Пульс | L11: Северная Звезда | M11: 1 | N11: 282.52 | O11: 340 | P11: 17 | Q11: 9 | R11: 200010000734 | S11: 29 | T11: 1 | U11: 2
A12: 44774 | B12: 0.37849537 | C12: 1277 | D12: 13002561 | E12: 13 | F12: 22589 | G12: Розничная реализация | H12: 18 | I12: 122156 | J12: КСИМЕЛИН ЭКСТРА 84МКГ/ДОЗА+70МКГ/ДОЗА 10МЛ. №1 НАЗАЛ.СПРЕЙ ДОЗИР. ФЛ. | K12: Пульс | L12: ТАКЕДА ФАРМАСЬЮТИКАЛ КОМПАНИ ЛИМИТЕД | M12: 1 | N12: 210.25 | O12: 284 | P12: 0 | Q12: NULL | R12: NULL | S12: 29 | T12: 1 | U12: 1
A13: 44774 | B13: 0.38320602 | C13: 1278 | D13: 13002561 | E13: 13 | F13: 22589 | G13: Розничная реализация | H13: 15 | I13: 608487 | J13: NF ВАТА ХИРУРГ. СТЕР. 100Г. /НЬЮФАРМ/ | K13: Фармкомплект ООО | L13: НьюФарм | M13: 1 | N13: 43.29 | O13: 71 | P13: 7 | Q13: 9 | R13: 200010001758 | S13: 29 | T13: 1 | U13: 1
A14: 44774 | B14: 0.38320602 | C14: 1278 | D14: 13002561 | E14: 13 | F14: 22589 | G14: Розничная реализация | H14: 15 | I14: 528004 | J14: СТОПСЕПТ ПЛЮС 90% 100МЛ. ДЕЗ.СР-ВО ФЛ. | K14: Авеста | L14: ГИППОКРАТ ООО | M14: 1 | N14: 35.52 | O14: 58 | P14: 5 | Q14: 9 | R14: 200010001758 | S14: 29 | T14: 1 | U14: 2
A15: 44774 | B15: 0.38756944 | C15: 1279 | D15: 13002561 | E15: 13 | F15: 22589 | G15: Розничная реализация | H15: 15 | I15: 443174 | J15: ПАСКАЛЬ ШПРИЦ 3-Х КОМП. 2МЛ. С ИГЛОЙ 23G 0,6Х30ММ. №10 [PASCAL] | K15: Катрен г.Химки | L15: ПАСКАЛЬ МЕДИКАЛ | M15: 1 | N15: 65.13 | O15: 103 | P15: 0 | Q15: NULL | R15: NULL | S15: 29 | T15: 1 | U15: 1
A16: 44774 | B16: 0.44326389 | C16: 1294 | D16: 13002561 | E16: 13 | F16: 22589 | G16: Розничная реализация | H16: 18 | I16: 443174 | J16: ПАСКАЛЬ ШПРИЦ 3-Х КОМП. 2МЛ. С ИГЛОЙ 23G 0,6Х30ММ. №10 [PASCAL] | K16: Катрен г.Химки | L16: ПАСКАЛЬ МЕДИКАЛ | M16: 1 | N16: 65.13 | O16: 103 | P16: 0 | Q16: NULL | R16: NULL | S16: 29 | T16: 1 | U16: 3
A17: 44774 | B17: 0.39586806 | C17: 1280 | D17: 13002561 | E17: 13 | F17: 22589 | G17: Розничная реализация | H17: 15 | I17: 21372 | J17: КЛОТРИМАЗОЛ 1% 20Г. КРЕМ Д/НАРУЖ.ПРИМ. ТУБА /ХИПЕРИОН/РУМЫНИЯ/ | K17: Пульс | L17: HYPERION SA (ХИПЕРИОН ) | M17: 1 | N17: 86.28 | O17: 123 | P17: 0 | Q17: NULL | R17: NULL | S17: 29 | T17: 1 | U17: 1
A18: 44774 | B18: 0.39586806 | C18: 1280 | D18: 13002561 | E18: 13 | F18: 22589 | G18: Розничная реализация | H18: 15 | I18: 365627 | J18: РИНОНОРМ-ТЕВА 0,1% 140МКГ/ДОЗА 20МЛ. НАЗАЛ.СПРЕЙ ФЛ. /ТЕВА/ | K18: ГРАНД КАПИТАЛ СМОЛЕНСК ООО ФК | L18: ТЕВА ЧЕШСКОЕ ПРЕДПРИЯТИЕ | M18: 1 | N18: 78.24 | O18: 96 | P18: 0 | Q18: NULL | R18: NULL | S18: 29 | T18: 1 | U18: 2
A19: 44774 | B19: 0.68071759 | C19: 1373 | D19: 13002561 | E19: 13 | F19: 22589 | G19: Розничная реализация | H19: 18 | I19: 365627 | J19: РИНОНОРМ-ТЕВА 0,1% 140МКГ/ДОЗА 20МЛ. НАЗАЛ.СПРЕЙ ФЛ. /ТЕВА/ | K19: ГРАНД КАПИТАЛ СМОЛЕНСК ООО ФК | L19: ТЕВА ЧЕШСКОЕ ПРЕДПРИЯТИЕ | M19: 1 | N19: 78.24 | O19: 96 | P19: 0 | Q19: NULL | R19: NULL | S19: 29 | T19: 1 | U19: 1
A20: 44774 | B20: 0.40825231 | C20: 1281 | D20: 13002561 | E20: 13 | F20: 22589 | G20: Розничная реализация | H20: 15 | I20: 12625 | J20: ДЮФАЛАК 667МГ/МЛ. 500МЛ. СИРОП ФЛ. +МЕРН.СТАКАН /ЭББОТТ/СОЛВЕЙ/ | K20: Арал плюс | L20: Abbott Japan Co ( ЭББОТТ ) | M20: 1 | N20: 455.9 | O20: 553 | P20: 16 | Q20: 9 | R20: 200010001617 | S20: 29 | T20: 1 | U20: 1
A21: 44774 | B21: 0.41150463 | C21: 1282 | D21: 13002561 | E21: 13 | F21: 22589 | G21: Розничная реализация | H21: 18 | I21: 67565 | J21: ГЕЛАДРИНК ФОРТЕ ПОР. Д/ПРИЕМА ВНУТРЬ АПЕЛЬСИН 420Г. БАНКА | K21: ВИТТА КОМПАНИ ООО | L21: ОРЛИНГ | M21: 1 | N21: 3638.1 | O21: 4985 | P21: 498 | Q21: 9 | R21: 200010004830 | S21: 29 | T21: 1 | U21: 1
A22: 44774 | B22: 0.41150463 | C22: 1282 | D22: 13002561 | E22: 13 | F22: 22589 | G22: Розничная реализация | H22: 18 | I22: 507949 | J22: ПИРАЦЕТАМ 200МГ. №60 ТАБ. П/П/О /ОБНОВЛЕНИЕ/ | K22: ГК Надежда Фарм | L22: ОБНОВЛЕНИЕ ПФК | M22: 1 | N22: 60.22 | O22: 73 | P22: 3 | Q22: 9 | R22: 200010004830 | S22: 29 | T22: 1 | U22: 2
A23: 44774 | B23: 0.4140162 | C23: 1283 | D23: 13002561 | E23: 13 | F23: 22589 | G23: Розничная реализация | H23: 15 | I23: 461654 | J23: МАГНЕЛИС В6 №120 ТАБ. П/О | K23: Катрен г.Химки | L23: ФАРМСТАНДАРТ УФАВИТА | M23: 1 | N23: 677.2 | O23: 779 | P23: 54 | Q23: 9 | R23: 200010020913 | S23: 29 | T23: 1 | U23: 2
A24: 44774 | B24: 0.4140162 | C24: 1283 | D24: 13002561 | E24: 13 | F24: 22589 | G24: Розничная реализация | H24: 15 | I24: 7697 | J24: МЕЗИМ-ФОРТЕ №80 ТАБ. П/О /БЕРЛИН-ХЕМИ/ | K24: Пульс | L24: Берлин-Хеми АГ/Менарини Групп (Menarini ) | M24: 1 | N24: 248.34 | O24: 302 | P24: 15 | Q24: 9 | R24: 200010020913 | S24: 29 | T24: 1 | U24: 3
A25: 44774 | B25: 0.4140162 | C25: 1283 | D25: 13002561 | E25: 13 | F25: 22589 | G25: Розничная реализация | H25: 15 | I25: 340968 | J25: КАЛЬЦИЙ Д3 НИКОМЕД 500МГ.+200МЕ №60 КЛУБНИКА+АРБУЗ ТАБ.ЖЕВ. | K25: Пульс | L25: ТАКЕДА ФАРМАСЬЮТИКАЛ КОМПАНИ ЛИМИТЕД | M25: 1 | N25: 403.68 | O25: 533 | P25: 37 | Q25: 9 | R25: 200010020913 | S25: 29 | T25: 1 | U25: 1
A26: 44774 | B26: 0.41548611 | C26: 1284 | D26: 13002561 | E26: 13 | F26: 22589 | G26: Розничная реализация | H26: 15 | I26: 530607 | J26: ЭКСПРЕСС-ТЕСТ НА А/ТЕЛА COVID-19 LGG/LGM | K26: Арал плюс | L26: ИМТЭК ООО | M26: 2 | N26: 619.88 | O26: 862 | P26: 172 | Q26: 9 | R26: 200010017394 | S26: 29 | T26: 1 | U26: 1
A27: 44774 | B27: 0.41795139 | C27: 1285 | D27: 13002561 | E27: 13 | F27: 22589 | G27: Розничная реализация | H27: 18 | I27: 330172 | J27: БОБС ЛЕДЕНЦЫ Д/ГОРЛА 35Г. ЭКСТРА МЕНТОЛ №10 | K27: Протек | L27: МАК-ИВАНОВО | M27: 1 | N27: 23.98 | O27: 39 | P27: 0 | Q27: NULL | R27: NULL | S27: 29 | T27: 1 | U27: 1
A28: 44774 | B28: 0.41947917 | C28: 1286 | D28: 13002561 | E28: 13 | F28: 22589 | G28: Розничная реализация | H28: 18 | I28: 393315 | J28: ЦИТРАМОН П №10 ТАБ. /ФАРМСТАНДАРТ/ | K28: Катрен г.Химки | L28: ФАРМСТАНДАРТ ЛЕКСРЕДСТВА ОАО | M28: 1 | N28: 16.21 | O28: 25 | P28: 0 | Q28: NULL | R28: NULL | S28: 29 | T28: 1 | U28: 1
A29: 44774 | B29: 0.41947917 | C29: 1286 | D29: 13002561 | E29: 13 | F29: 22589 | G29: Розничная реализация | H29: 18 | I29: 393315 | J29: ЦИТРАМОН П №10 ТАБ. /ФАРМСТАНДАРТ/ | K29: Катрен г.Химки | L29: ФАРМСТАНДАРТ ЛЕКСРЕДСТВА ОАО | M29: 1 | N29: 16.21 | O29: 25 | P29: 0 | Q29: NULL | R29: NULL | S29: 29 | T29: 1 | U29: 2
A30: 44774 | B30: 0.62164352 | C30: 1362 | D30: 13002561 | E30: 13 | F30: 22589 | G30: Розничная реализация | H30: 18 | I30: 393315 | J30: ЦИТРАМОН П №10 ТАБ. /ФАРМСТАНДАРТ/ | K30: Катрен г.Химки | L30: ФАРМСТАНДАРТ ЛЕКСРЕДСТВА ОАО | M30: 1 | N30: 16.21 | O30: 25 | P30: 0 | Q30: NULL | R30: NULL | S30: 29 | T30: 1 | U30: 3
A31: 44774 | B31: 0.42930556 | C31: 1287 | D31: 13002561 | E31: 13 | F31: 22589 | G31: Розничная реализация | H31: 18 | I31: 377588 | J31: ТИЗИН КЛАССИК 0,1% 10МЛ. НАЗАЛ.СПРЕЙ ФЛ. /ДЖОНСОН/ | K31: Катрен г.Химки | L31: ДЕЛЬФАРМ ОРЛЕАН ( DELPHARM ) | M31: 1 | N31: 84.17 | O31: 100 | P31: 41.09 | Q31: 925 | R31: 200000000492 | S31: 29 | T31: 1 | U31: 3
A32: 44774 | B32: 0.42930556 | C32: 1287 | D32: 13002561 | E32: 13 | F32: 22589 | G32: Розничная реализация | H32: 18 | I32: 297336 | J32: ЛАКОМКА ПОМАДА ГИГИЕН. ЯГОДНЫЙ МИКС 2,8Г. /АВАНТА/ | K32: Протек | L32: АВАНТА ОАО | M32: 1 | N32: 45.17 | O32: 74 | P32: 30.41 | Q32: 925 | R32: 200000000492 | S32: 29 | T32: 1 | U32: 1
A33: 44774 | B33: 0.42930556 | C33: 1287 | D33: 13002561 | E33: 13 | F33: 22589 | G33: Розничная реализация | H33: 18 | I33: 2302 | J33: ОМЕЗ 20МГ. №30 КАПС. /Д-Р РЕДДИ/ | K33: ВИТТА КОМПАНИ ООО | L33: ДОКТОР РЕДДИ С ЛАБ / Dr. REDDY's ) | M33: 1 | N33: 148.28 | O33: 174 | P33: 71.5 | Q33: 925 | R33: 200000000492 | S33: 29 | T33: 1 | U33: 2
A34: 44774 | B34: 0.43451389 | C34: 1288 | D34: 13002561 | E34: 13 | F34: 22589 | G34: Розничная реализация | H34: 15 | I34: 23396 | J34: ЭВКАЛИПТ М №24 ПАСТИЛКИ | K34: ООО "Акцентмед" | L34: ДР.АУФДЕРМАУР АГ | M34: 2 | N34: 248.26 | O34: 336 | P34: 0 | Q34: NULL | R34: NULL | S34: 29 | T34: 1 | U34: 1
A35: 44774 | B35: 0.43633102 | C35: 1289 | D35: 13002561 | E35: 13 | F35: 22589 | G35: Розничная реализация | H35: 15 | I35: 143150 | J35: АЗАРГА 10МГ/МЛ.+5МГ/МЛ. 5МЛ. №1 ГЛ.КАПЛИ ФЛ./КАП. | K35: ВИТТА КОМПАНИ ООО | L35: АЛКОН Куврер н.в. (ALCON ) | M35: 1 | N35: 1042.25 | O35: 1314 | P35: 91 | Q35: 9 | R35: 200010000065 | S35: 29 | T35: 1 | U35: 1
A36: 44774 | B36: 0.43633102 | C36: 1289 | D36: 13002561 | E36: 13 | F36: 22589 | G36: Розничная реализация | H36: 15 | I36: 263189 | J36: ТРАВАТАН 0,004% 2,5МЛ. №3 ГЛ.КАПЛИ ФЛ./КАП. | K36: Катрен г.Химки | L36: ALCON COUVREUR (АЛКОН ) | M36: 1 | N36: 1576.65 | O36: 1971 | P36: 137 | Q36: 9 | R36: 200010000065 | S36: 29 | T36: 1 | U36: 5
A37: 44774 | B37: 0.43633102 | C37: 1289 | D37: 13002561 | E37: 13 | F37: 22589 | G37: Розничная реализация | H37: 15 | I37: 519407 | J37: ЙОДА 5% 10МЛ. СПИРТ. Р-Р ФЛ. /ЯРОСЛАВСКАЯ ФФ/ | K37: Катрен г.Химки | L37: ЯРОСЛАВСКАЯ ФАРМ. ФАБРИКА | M37: 1 | N37: 34.25 | O37: 53 | P37: 3 | Q37: 9 | R37: 200010000065 | S37: 29 | T37: 1 | U37: 2
A38: 44774 | B38: 0.43633102 | C38: 1289 | D38: 13002561 | E38: 13 | F38: 22589 | G38: Розничная реализация | H38: 15 | I38: 345211 | J38: ОМЕПРАЗОЛ 20МГ. №30 КАПС. /ПРОИЗВОДСТВО МЕДИКАМЕНТОВ/ | K38: ГРАНД КАПИТАЛ СМОЛЕНСК ООО ФК | L38: ПРОИЗВОДСТВО МЕДИКАМЕНТОВ ООО | M38: 1 | N38: 25.28 | O38: 30 | P38: 1 | Q38: 9 | R38: 200010000065 | S38: 29 | T38: 1 | U38: 3
A39: 44774 | B39: 0.47800926 | C39: 1307 | D39: 13002561 | E39: 13 | F39: 22589 | G39: Розничная реализация | H39: 18 | I39: 345211 | J39: ОМЕПРАЗОЛ 20МГ. №30 КАПС. /ПРОИЗВОДСТВО МЕДИКАМЕНТОВ/ | K39: ГРАНД КАПИТАЛ СМОЛЕНСК ООО ФК | L39: ПРОИЗВОДСТВО МЕДИКАМЕНТОВ ООО | M39: 1 | N39: 25.28 | O39: 30 | P39: 1 | Q39: 9 | R39: 200010000452 | S39: 29 | T39: 1 | U39: 1
A40: 44774 | B40: 0.50565972 | C40: 1319 | D40: 13002561 | E40: 13 | F40: 22589 | G40: Розничная реализация | H40: 18 | I40: 345211 | J40: ОМЕПРАЗОЛ 20МГ. №30 КАПС. /ПРОИЗВОДСТВО МЕДИКАМЕНТОВ/ | K40: ГРАНД КАПИТАЛ СМОЛЕНСК ООО ФК | L40: ПРОИЗВОДСТВО МЕДИКАМЕНТОВ ООО | M40: 1 | N40: 25.28 | O40: 30 | P40: 1 | Q40: 9 | R40: 200010015482 | S40: 29 | T40: 1 | U40: 3
...

Sheet КОЛИЧЕСТВО
A3: Названия строк | B3: Сумма по столбцу DR_Kol | D3: Названия | E3: Сумма по столбцу DR_Kol | F3: Доля | G3: Накопит. | H3: КОЛ | I3: СУМ ПРОД | J3: МЕСЯЧ. Рент
A4: 911-ВЕНОЛГОН ГЕЛЬ Д/НОГ ПРИ ТЯЖЕСТИ,БОЛИ,ОТЕКАХ 100МЛ. ТУБА | B4: 1 | D4: ЛЕЙКОПЛАСТЫРЬ БАКТЕР. 2,5Х7,2 №1 /ВЕРОФАРМ/ | E4: 68 | F4: =E4/SUM($E$4:$E$806) -> 0.042265927 | G4: =F4 -> 0.042265927 | H4: =IF(G4<0.8, "A", IF(G4<0.95, "B","C")) -> A | I4: =VLOOKUP(D4,'СУММА ПРОДАЖ'!J:N, 5, FALSE) -> B | J4: =VLOOKUP(D4, 'МЕСЯЧНАЯ ОБОР.'!$V$4:$W$806, 2, FALSE) -> A
A5: 911-ГЕЛЬ-БАЛЬЗАМ Д/НОГ КОНСКИЙ КАШТАН 100МЛ. ТУБА | B5: 1 | D5: НАФТИЗИН 0,1% 15МЛ. НАЗАЛ.КАПЛИ ФЛ./КАП. /СЛАВЯНСКАЯ АПТЕКА/ | E5: 35 | F5: =E5/SUM($E$4:$E$806) -> 0.021754521 | G5: =F5+G4 -> 0.064020449 | H5: =IF(G5<0.8, "A", IF(G5<0.95, "B","C")) -> A | I5: =VLOOKUP(D5,'СУММА ПРОДАЖ'!J:N, 5, FALSE) -> B | J5: =VLOOKUP(D5, 'МЕСЯЧНАЯ ОБОР.'!$V$4:$W$806, 2, FALSE) -> A
A6: 911-ГЕЛЬ-БАЛЬЗАМ Д/СУСТАВОВ РАЗОГР. ОКОПНИК+МУРАВ.К-ТА 100МЛ. | B6: 1 | D6: ПАКЕТ | E6: 26 | F6: =E6/SUM($E$4:$E$806) -> 0.016160502 | G6: =F6+G5 -> 0.08018095 | H6: =IF(G6<0.8, "A", IF(G6<0.95, "B","C")) -> A | I6: =VLOOKUP(D6,'СУММА ПРОДАЖ'!J:N, 5, FALSE) -> C | J6: =VLOOKUP(D6, 'МЕСЯЧНАЯ ОБОР.'!$V$4:$W$806, 2, FALSE) -> A
A7: L-ТИРОКСИН 100МКГ. №100 ТАБ. /БЕРЛИН ХЕМИ/ | B7: 1 | D7: ВАЛИДОЛ 60МГ. №10 ТАБ. ПОДЪЯЗЫЧ. /ФАРМСТАНДАРТ/ | E7: 25 | F7: =E7/SUM($E$4:$E$806) -> 0.015538944 | G7: =F7+G6 -> 0.095719894 | H7: =IF(G7<0.8, "A", IF(G7<0.95, "B","C")) -> A | I7: =VLOOKUP(D7,'СУММА ПРОДАЖ'!J:N, 5, FALSE) -> A | J7: =VLOOKUP(D7, 'МЕСЯЧНАЯ ОБОР.'!$V$4:$W$806, 2, FALSE) -> A
A8: L-ТИРОКСИН 150МКГ. №100 ТАБ. /БЕРЛИН ХЕМИ/ | B8: 1 | D8: БОРНАЯ К-ТА 10Г. ДЕЗ.СР-ВО ПОР. (НДС 20%) | E8: 22 | F8: =E8/SUM($E$4:$E$806) -> 0.013674271 | G8: =F8+G7 -> 0.10939416 | H8: =IF(G8<0.8, "A", IF(G8<0.95, "B","C")) -> A | I8: =VLOOKUP(D8,'СУММА ПРОДАЖ'!J:N, 5, FALSE) -> B | J8: =VLOOKUP(D8, 'МЕСЯЧНАЯ ОБОР.'!$V$4:$W$806, 2, FALSE) -> A
A9: L-ТИРОКСИН 50МКГ. №50 ТАБ. /БЕРЛИН ХЕМИ/ | B9: 2 | D9: ГЕМАТОГЕН РУССКИЙ ДЕТСКИЙ 40Г. ПЛИТКА /ФАРМ-ПРО/ | E9: 17 | F9: =E9/SUM($E$4:$E$806) -> 0.010566482 | G9: =F9+G8 -> 0.11996065 | H9: =IF(G9<0.8, "A", IF(G9<0.95, "B","C")) -> A | I9: =VLOOKUP(D9,'СУММА ПРОДАЖ'!J:N, 5, FALSE) -> B | J9: =VLOOKUP(D9, 'МЕСЯЧНАЯ ОБОР.'!$V$4:$W$806, 2, FALSE) -> A
A10: L-ТИРОКСИН 75МКГ. №100 ТАБ. /БЕРЛИН ХЕМИ/ | B10: 3 | D10: КОРВАЛОЛ 25МЛ. КАПЛИ Д/ПРИЕМА ВНУТРЬ ФЛ. И/У /ФАРМСТАНДАРТ ЛЕКСРЕДСТВА/ | E10: 14 | F10: =E10/SUM($E$4:$E$806) -> 0.0087018086 | G10: =F10+G9 -> 0.12866246 | H10: =IF(G10<0.8, "A", IF(G10<0.95, "B","C")) -> A | I10: =VLOOKUP(D10,'СУММА ПРОДАЖ'!J:N, 5, FALSE) -> A | J10: =VLOOKUP(D10, 'МЕСЯЧНАЯ ОБОР.'!$V$4:$W$806, 2, FALSE) -> A
A11: NF ВАТА ХИРУРГ. СТЕР. 100Г. /НЬЮФАРМ/ | B11: 1 | D11: ЛЕЙКОПЛАСТЫРЬ БАКТЕР. 4Х10 №1 /ВЕРОФАРМ/ | E11: 14 | F11: =E11/SUM($E$4:$E$806) -> 0.0087018086 | G11: =F11+G10 -> 0.13736426 | H11: =IF(G11<0.8, "A", IF(G11<0.95, "B","C")) -> A | I11: =VLOOKUP(D11,'СУММА ПРОДАЖ'!J:N, 5, FALSE) -> C | J11: =VLOOKUP(D11, 'МЕСЯЧНАЯ ОБОР.'!$V$4:$W$806, 2, FALSE) -> A
A12: АДЖИСЕПТ МЕД+ЛИМОН №24 ТАБ. Д/РАСС. | B12: 1 | D12: ЛЕЙКОПЛАСТЫРЬ БАКТЕР. 6X10 №1 /ВЕРОФАРМ/ | E12: 13 | F12: =E12/SUM($E$4:$E$806) -> 0.0080802508 | G12: =F12+G11 -> 0.14544451 | H12: =IF(G12<0.8, "A", IF(G12<0.95, "B","C")) -> A | I12: =VLOOKUP(D12,'СУММА ПРОДАЖ'!J:N, 5, FALSE) -> C | J12: =VLOOKUP(D12, 'МЕСЯЧНАЯ ОБОР.'!$V$4:$W$806, 2, FALSE) -> A
A13: АДЖИСЕПТ МЕНТОЛ+ЭВКАЛИПТ №24 ТАБ. Д/РАСС. | B13: 1 | D13: МЕНОВАЗИН 40МЛ. №1 СПИРТ. Р-Р Д/НАРУЖ.ПРИМ. ФЛ. /САМАРАМЕДПРОМ/ | E13: 13 | F13: =E13/SUM($E$4:$E$806) -> 0.0080802508 | G13: =F13+G12 -> 0.15352477 | H13: =IF(G13<0.8, "A", IF(G13<0.95, "B","C")) -> A | I13: =VLOOKUP(D13,'СУММА ПРОДАЖ'!J:N, 5, FALSE) -> A | J13: =VLOOKUP(D13, 'МЕСЯЧНАЯ ОБОР.'!$V$4:$W$806, 2, FALSE) -> A
A14: АЕВИТ 200МГ. №20 КАПС. (БАД) /МЕЛИГЕН/ | B14: 1 | D14: ПЕРЕКИСЬ ВОДОРОДА 3% 100МЛ. №1 Р-Р ДЕЗ.СР-ВО ФЛ. (НДС 20%) | E14: 13 | F14: =E14/SUM($E$4:$E$806) -> 0.0080802508 | G14: =F14+G13 -> 0.16160502 | H14: =IF(G14<0.8, "A", IF(G14<0.95, "B","C")) -> A | I14: =VLOOKUP(D14,'СУММА ПРОДАЖ'!J:N, 5, FALSE) -> B | J14: =VLOOKUP(D14, 'МЕСЯЧНАЯ ОБОР.'!$V$4:$W$806, 2, FALSE) -> A
A15: АЗАРГА 10МГ/МЛ.+5МГ/МЛ. 5МЛ. №1 ГЛ.КАПЛИ ФЛ./КАП. | B15: 2 | D15: РАУНАТИН 2МГ. №50 ТАБ. П/О /ЗДОРОВЬЕ/ | E15: 13 | F15: =E15/SUM($E$4:$E$806) -> 0.0080802508 | G15: =F15+G14 -> 0.16968527 | H15: =IF(G15<0.8, "A", IF(G15<0.95, "B","C")) -> A | I15: =VLOOKUP(D15,'СУММА ПРОДАЖ'!J:N, 5, FALSE) -> A | J15: =VLOOKUP(D15, 'МЕСЯЧНАЯ ОБОР.'!$V$4:$W$806, 2, FALSE) -> A
A16: АЗИТРОМИЦИН 500МГ. №3 КАПС. /ПРОИЗВОДСТВО МЕДИКАМЕНТОВ/ ПроМед/ | B16: 2 | D16: Карта LOYALITY 0,01Р | E16: 12 | F16: =E16/SUM($E$4:$E$806) -> 0.007458693 | G16: =F16+G15 -> 0.17714396 | H16: =IF(G16<0.8, "A", IF(G16<0.95, "B","C")) -> A | I16: =VLOOKUP(D16,'СУММА ПРОДАЖ'!J:N, 5, FALSE) -> C | J16: =VLOOKUP(D16, 'МЕСЯЧНАЯ ОБОР.'!$V$4:$W$806, 2, FALSE) -> A
... A806: ЮНИДОКС СОЛЮТАБ 100МГ. №20 ТАБ.ДИСПЕРГ. /АСТЕЛЛАС/ | B806: 1 | D806: ХАРТМАНН КОСМОПОР Е ПОВЯЗКА 7,2Х5СМ №50 П/ОПЕР. САМОКЛ. СТЕР. /АРТ.9008705/ [HARTMANN COSMOPOR] | E806: 0.04 | F806: =E806/SUM($E$4:$E$806) -> 2.486231e-05 | G806: =F806+G805 -> 1 | H806: =IF(G806<0.8, "A", IF(G806<0.95, "B","C")) -> C | I806: =VLOOKUP(D806,'СУММА ПРОДАЖ'!J:N, 5, FALSE) -> C | J806: =VLOOKUP(D806, 'МЕСЯЧНАЯ ОБОР.'!$V$4:$W$806, 2, FALSE) -> C
A807: Общий итог | B807: 1608.861

Sheet СУММА ПРОДАЖ
A1: DR_NDrugs | B1: DR_Croz (розничная цена) | C1: DR_Kol | D1: DR_Sdisc (сумма скидки) | E1: Сумма продаж | G1: Названия строк | H1: Сумма по столбцу Сумма продаж | J1: Названия строк | K1: Сумма по столбцу Сумма продаж | L1: Доля | M1: Накоп. Доля
A2: ГАСТАЛ №12 ТАБ. Д/РАСС. | B2: 270 | C2: 1 | D2: 0 | E2: =C2*B2-D2 -> 270 | G2: 911-ВЕНОЛГОН ГЕЛЬ Д/НОГ ПРИ ТЯЖЕСТИ,БОЛИ,ОТЕКАХ 100МЛ. ТУБА | H2: 120 | J2: ДЕТРАЛЕКС 1000МГ. №60 ТАБ. П/П/О | K2: 11948 | L2: =K2/SUM($K$2:$K$804) -> 0.032459264 | M2: =L2 -> 0.032459264 | N2: =IF(M2<0.8, "A", IF(M2<0.95,"B","C")) -> A
A3: ТОБРОПТ 0,3% 5МЛ. №1 ГЛ.КАПЛИ ФЛ./КАП. /РОМФАРМ/ | B3: 127 | C3: 1 | D3: 6 | E3: =C3*B3-D3 -> 121 | G3: 911-ГЕЛЬ-БАЛЬЗАМ Д/НОГ КОНСКИЙ КАШТАН 100МЛ. ТУБА | H3: 105 | J3: ЭЛИКВИС 5МГ. №60 ТАБ. П/П/О /ПФАЙЗЕР/БРИСТОЛ-МАЙЕРС/ | K3: 5126 | L3: =K3/SUM($K$2:$K$804) -> 0.013925861 | M3: =L3+M2 -> 0.046385126 | N3: =IF(M3<0.8, "A", IF(M3<0.95,"B","C")) -> A
A4: ЭЛИКВИС 5МГ. №60 ТАБ. П/П/О /ПФАЙЗЕР/БРИСТОЛ-МАЙЕРС/ | B4: 2563 | C4: 1 | D4: 76 | E4: =C4*B4-D4 -> 2487 | G4: 911-ГЕЛЬ-БАЛЬЗАМ Д/СУСТАВОВ РАЗОГР. ОКОПНИК+МУРАВ.К-ТА 100МЛ. | H4: 122 | J4: ГЕЛАДРИНК ФОРТЕ ПОР. Д/ПРИЕМА ВНУТРЬ АПЕЛЬСИН 420Г. БАНКА | K4: 4985 | L4: =K4/SUM($K$2:$K$804) -> 0.013542805 | M4: =L4+M3 -> 0.05992793 | N4: =IF(M4<0.8, "A", IF(M4<0.95,"B","C")) -> A
A5: АРБИДОЛ МАКСИМУМ 200МГ. №10 КАПС. /ОТИСИФАРМ/ФАРМСТАНДАРТ/ | B5: 541 | C5: 1 | D5: 0 | E5: =C5*B5-D5 -> 541 | G5: L-ТИРОКСИН 100МКГ. №100 ТАБ. /БЕРЛИН ХЕМИ/ | H5: 153 | J5: ОМРОН ТОНОМЕТР M2 БАЗИК АВТОМАТ АДАПТЕР /АРТ.HEM-7121-ARU/ [OMRON] | K5: 3832 | L5: =K5/SUM($K$2:$K$804) -> 0.010410437 | M5: =L5+M4 -> 0.070338367 | N5: =IF(M5<0.8, "A", IF(M5<0.95,"B","C")) -> A
A6: ЭНАМ 2,5МГ. №20 ТАБ. /Д-Р РЕДДИ/ | B6: 22 | C6: 1 | D6: 1 | E6: =C6*B6-D6 -> 21 | G6: L-ТИРОКСИН 150МКГ. №100 ТАБ. /БЕРЛИН ХЕМИ/ | H6: 177 | J6: ИНЪЕКТРАН 100МГ/МЛ. 2МЛ. №10 Р-Р Д/В/М АМП. | K6: 3697 | L6: =K6/SUM($K$2:$K$804) -> 0.010043681 | M6: =L6+M5 -> 0.080382048 | N6: =IF(M6<0.8, "A", IF(M6<0.95,"B","C")) -> A
A7: ЭНАМ 2,5МГ. №20 ТАБ. /Д-Р РЕДДИ/ | B7: 22 | C7: 1 | D7: 1 | E7: =C7*B7-D7 -> 21 | G7: L-ТИРОКСИН 50МКГ. №50 ТАБ. /БЕРЛИН ХЕМИ/ | H7: 199 | J7: ЛИТТЛ ДОКТОР ТОНОМЕТР LD-51U АВТОМАТ НА ПЛЕЧО 22-42СМ. +АДАПТЕР [LITTLE DOCTOR] | K7: 3497 | L7: =K7/SUM($K$2:$K$804) -> 0.0095003388 | M7: =L7+M6 -> 0.089882387 | N7: =IF(M7<0.8, "A", IF(M7<0.95,"B","C")) -> A
A8: КЛОПИДОГРЕЛ-СЗ 75МГ. №28 ТАБ. П/П/О /СЕВЕРНАЯ ЗВЕЗДА/ | B8: 475 | C8: 1 | D8: 23 | E8: =C8*B8-D8 -> 452 | G8: L-ТИРОКСИН 75МКГ. №100 ТАБ. /БЕРЛИН ХЕМИ/ | H8: 432 | J8: ВЕССЕЛ ДУЭ Ф 250ЕД №60 КАПС. | K8: 3482 | L8: =K8/SUM($K$2:$K$804) -> 0.0094595881 | M8: =L8+M7 -> 0.099341975 | N8: =IF(M8<0.8, "A", IF(M8<0.95,"B","C")) -> A
A9: КО-ВАМЛОСЕТ 5МГ.+160МГ.+12,5МГ. №30 ТАБ. П/П/О | B9: 693 | C9: 1 | D9: 48 | E9: =C9*B9-D9 -> 645 | G9: NF ВАТА ХИРУРГ. СТЕР. 100Г. /НЬЮФАРМ/ | H9: 71 | J9: ПРАДАКСА 110МГ. №180 КАПС. /БЕРИНГЕР/ | K9: 3458.3333 | L9: =K9/SUM($K$2:$K$804) -> 0.0093952925 | M9: =L9+M8 -> 0.10873727 | N9: =IF(M9<0.8, "A", IF(M9<0.95,"B","C")) -> A
A10: АТОРВАСТАТИН-СЗ 20МГ. №60 ТАБ. П/П/О /СЕВЕРНАЯ ЗВЕЗДА/ | B10: 418 | C10: 1 | D10: 20 | E10: =C10*B10-D10 -> 398 | G10: АДЖИСЕПТ МЕД+ЛИМОН №24 ТАБ. Д/РАСС. | H10: 213 | J10: ДЮФАЛАК 667МГ/МЛ. 1000МЛ. СИРОП ФЛ. +МЕРН.СТАКАН /ЭББОТТ/СОЛВЕЙ/ | K10: 2703.89 | L10: =K10/SUM($K$2:$K$804) -> 0.007345688 | M10: =L10+M9 -> 0.11608296 | N10: =IF(M10<0.8, "A", IF(M10<0.95,"B","C")) -> A
A11: АТОРВАСТАТИН-СЗ 40МГ. №30 ТАБ. П/П/О /СЕВЕРНАЯ ЗВЕЗДА/ | B11: 340 | C11: 1 | D11: 17 | E11: =C11*B11-D11 -> 323 | G11: АДЖИСЕПТ МЕНТОЛ+ЭВКАЛИПТ №24 ТАБ. Д/РАСС. | H11: 216 | J11: ЛОНГИДАЗА 3000МЕ №10 СУПП. РЕКТ./ВАГИН. | K11: 2642 | L11: =K11/SUM($K$2:$K$804) -> 0.0071775508 | M11: =L11+M10 -> 0.12326051 | N11: =IF(M11<0.8, "A", IF(M11<0.95,"B","C")) -> A
A12: КСИМЕЛИН ЭКСТРА 84МКГ/ДОЗА+70МКГ/ДОЗА 10МЛ. №1 НАЗАЛ.СПРЕЙ ДОЗИР. ФЛ. | B12: 284 | C12: 1 | D12: 0 | E12: =C12*B12-D12 -> 284 | G12: АЕВИТ 200МГ. №20 КАПС. (БАД) /МЕЛИГЕН/ | H12: 49 | J12: АЗАРГА 10МГ/МЛ.+5МГ/МЛ. 5МЛ. №1 ГЛ.КАПЛИ ФЛ./КАП. | K12: 2628 | L12: =K12/SUM($K$2:$K$804) -> 0.0071395168 | M12: =L12+M11 -> 0.13040002 | N12: =IF(M12<0.8, "A", IF(M12<0.95,"B","C")) -> A
A13: NF ВАТА ХИРУРГ. СТЕР. 100Г. /НЬЮФАРМ/ | B13: 71 | C13: 1 | D13: 7 | E13: =C13*B13-D13 -> 64 | G13: АЗАРГА 10МГ/МЛ.+5МГ/МЛ. 5МЛ. №1 ГЛ.КАПЛИ ФЛ./КАП. | H13: 2628 | J13: ВИТАПРОСТ 10МГ. №10 СУПП. РЕКТ. /НИЖФАРМ/ | K13: 2596 | L13: =K13/SUM($K$2:$K$804) -> 0.007052582 | M13: =L13+M12 -> 0.13745261 | N13: =IF(M13<0.8, "A", IF(M13<0.95,"B","C")) -> A
A14: СТОПСЕПТ ПЛЮС 90% 100МЛ. ДЕЗ.СР-ВО ФЛ. | B14: 58 | C14: 1 | D14: 5 | E14: =C14*B14-D14 -> 53 | G14: АЗИТРОМИЦИН 500МГ. №3 КАПС. /ПРОИЗВОДСТВО МЕДИКАМЕНТОВ/ ПроМед/ | H14: 168 | J14: ТОНОМЕТР UA-604 П/АВТОМАТ [AND] | K14: 2456 | L14: =K14/SUM($K$2:$K$804) -> 0.0066722425 | M14: =L14+M13 -> 0.14412485 | N14: =IF(M14<0.8, "A", IF(M14<0.95,"B","C")) -> A
... A804: КОРВАЛОЛ 25МЛ. КАПЛИ Д/ПРИЕМА ВНУТРЬ ФЛ. И/У /ФАРМСТАНДАРТ ЛЕКСРЕДСТВА/ | B804: 26 | C804: 1 | D804: 1 | E804: =C804*B804-D804 -> 25 | G804: ЮНИДОКС СОЛЮТАБ 100МГ. №20 ТАБ.ДИСПЕРГ. /АСТЕЛЛАС/ | H804: 658 | J804: Карта LOYALITY 0,01Р | K804: 0.12 | L804: =K804/SUM($K$2:$K$804) -> 3.2600533e-07 | M804: =L804+M803 -> 1 | N804: =IF(M804<0.8, "A", IF(M804<0.95,"B","C")) -> C
A805: КОРВАЛОЛ 25МЛ. КАПЛИ Д/ПРИЕМА ВНУТРЬ ФЛ. И/У /ФАРМСТАНДАРТ ЛЕКСРЕДСТВА/ | B805: 26 | C805: 1 | D805: 1 | E805: =C805*B805-D805 -> 25 | G805: Общий итог | H805: 368092.14
A806: КОРВАЛОЛ 25МЛ. КАПЛИ Д/ПРИЕМА ВНУТРЬ ФЛ. И/У /ФАРМСТАНДАРТ ЛЕКСРЕДСТВА/ | B806: 26 | C806: 1 | D806: 1 | E806: =C806*B806-D806 -> 25
A807: КОРВАЛОЛ 25МЛ. КАПЛИ Д/ПРИЕМА ВНУТРЬ ФЛ. И/У /ФАРМСТАНДАРТ ЛЕКСРЕДСТВА/ | B807: 26 | C807: 1 | D807: 1 | E807: =C807*B807-D807 -> 25
A808: ГЛИЦИН 100МГ. №100 ТАБ. ПОДЪЯЗЫЧ. /БИОТИКИ/ | B808: 70 | C808: 1 | D808: 3 | E808: =C808*B808-D808 -> 67
A809: ГИПОСАРТ 16МГ. №28 ТАБ. | B809: 493 | C809: 1 | D809: 0 | E809: =C809*B809-D809 -> 493
A810: МЕКСИДОЛ 125МГ. №50 ТАБ. П/П/О /ФАРМАСОФТ/ЗИО ЗДОРОВЬЕ/ | B810: 490 | C810: 1 | D810: 0 | E810: =C810*B810-D810 -> 490
A811: МЕКСИДОЛ 125МГ. №50 ТАБ. П/П/О /ФАРМАСОФТ/ЗИО ЗДОРОВЬЕ/ | B811: 490 | C811: 1 | D811: 0 | E811: =C811*B811-D811 -> 490
A812: НЕО-АНГИН №24 ТАБ. Д/РАСС. САХ. | B812: 217 | C812: 1 | D812: 0 | E812: =C812*B812-D812 -> 217
A813: Д.ТАЙСС АНГИ СЕПТ МЕД+ЛИПА №24 ТАБ. Д/РАСС. | B813: 222 | C813: 1 | D813: 0 | E813: =C813*B813-D813 -> 222
A814: ФЕРРОГЕМАТОГЕН 50Г. ПАСТИЛКА ЖЕВ. (ПЛИТКА) | B814: 30 | C814: 2 | D814: 6 | E814: =C814*B814-D814 -> 54
A815: ФЕРРОГЕМАТОГЕН 50Г. ПАСТИЛКА ЖЕВ. (ПЛИТКА) | B815: 30 | C815: 1 | D815: 3 | E815: =C815*B815-D815 -> 27
A816: АСКОРБИНКА ЛУНТИК ВИТ.С №10 ТАБ. (30Г.) /ФАРМ-ПРО/ТИГОДА-ФАРМ/ | B816: 16 | C816: 1 | D816: 0 | E816: =C816*B816-D816 -> 16
A817: АСКОРБИНОВАЯ К-ТА 25МГ. ВИШНЯ №10 ТАБ. КРУТКА САХ. /АСКОПРОМ/ | B817: 11 | C817: 1 | D817: 0 | E817: =C817*B817-D817 -> 11
... A1449: ГЕМАТОГЕН РУССКИЙ КЕДРОВЫЙ ОРЕХ 40Г. ПЛИТКА /ФАРМ-ПРО/ | B1449: 30 | C1449: 1 | D1449: 3 | E1449: =C1449*B1449-D1449 -> 27

Sheet МЕСЯЧНАЯ ОБОР.
A1: DR_Dat | B1: DR_NDrugs | C1: DR_Kol
A2: 44774 | B2: ГАСТАЛ №12 ТАБ. Д/РАСС. | C2: 1 | F2: Сумма по столбцу DR_Kol | G2: Названия столбцов
A3: 44774 | B3: ТОБРОПТ 0,3% 5МЛ. №1 ГЛ.КАПЛИ ФЛ./КАП. /РОМФАРМ/ | C3: 1 | G3: 44774 | H3: 44775 | I3: 44776 | J3: 44777 | K3: 44778 | L3: Общий итог | P3: Общий итог | Q3: Месяч. Обор
A4: 44774 | B4: ЭЛИКВИС 5МГ. №60 ТАБ. П/П/О /ПФАЙЗЕР/БРИСТОЛ-МАЙЕРС/ | C4: 1 | F4: 911-ВЕНОЛГОН ГЕЛЬ Д/НОГ ПРИ ТЯЖЕСТИ,БОЛИ,ОТЕКАХ 100МЛ. ТУБА | G4: 1 | L4: 1 | O4: ЛЕЙКОПЛАСТЫРЬ БАКТЕР. 2,5Х7,2 №1 /ВЕРОФАРМ/ | P4: 68 | Q4: =(P4/5)*30 -> 408 | R4: =Q4/SUM($Q$4:$Q$806) -> 0.042265927 | S4: =R4 -> 0.042265927 | T4: =IF(S4<0.8,"A", IF(S4<0.95,"B","C")) -> A | V4: ЛЕЙКОПЛАСТЫРЬ БАКТЕР. 2,5Х7,2 №1 /ВЕРОФАРМ/ | W4: A
A5: 44774 | B5: АРБИДОЛ МАКСИМУМ 200МГ. №10 КАПС. /ОТИСИФАРМ/ФАРМСТАНДАРТ/ | C5: 1 | F5: 911-ГЕЛЬ-БАЛЬЗАМ Д/НОГ КОНСКИЙ КАШТАН 100МЛ. ТУБА | H5: 1 | L5: 1 | O5: НАФТИЗИН 0,1% 15МЛ. НАЗАЛ.КАПЛИ ФЛ./КАП. /СЛАВЯНСКАЯ АПТЕКА/ | P5: 35 | Q5: =(P5/5)*30 -> 210 | R5: =Q5/SUM($Q$4:$Q$806) -> 0.021754521 | S5: =R5+S4 -> 0.064020449 | T5: =IF(S5<0.8,"A", IF(S5<0.95,"B","C")) -> A | V5: НАФТИЗИН 0,1% 15МЛ. НАЗАЛ.КАПЛИ ФЛ./КАП. /СЛАВЯНСКАЯ АПТЕКА/ | W5: A
A6: 44774 | B6: ЭНАМ 2,5МГ. №20 ТАБ. /Д-Р РЕДДИ/ | C6: 1 | F6: 911-ГЕЛЬ-БАЛЬЗАМ Д/СУСТАВОВ РАЗОГР. ОКОПНИК+МУРАВ.К-ТА 100МЛ. | I6: 1 | L6: 1 | O6: ПАКЕТ | P6: 26 | Q6: =(P6/5)*30 -> 156 | R6: =Q6/SUM($Q$4:$Q$806) -> 0.016160502 | S6: =R6+S5 -> 0.08018095 | T6: =IF(S6<0.8,"A", IF(S6<0.95,"B","C")) -> A | V6: ПАКЕТ | W6: A
A7: 44774 | B7: ЭНАМ 2,5МГ. №20 ТАБ. /Д-Р РЕДДИ/ | C7: 1 | F7: L-ТИРОКСИН 100МКГ. №100 ТАБ. /БЕРЛИН ХЕМИ/ | G7: 1 | L7: 1 | O7: ВАЛИДОЛ 60МГ. №10 ТАБ. ПОДЪЯЗЫЧ. /ФАРМСТАНДАРТ/ | P7: 25 | Q7: =(P7/5)*30 -> 150 | R7: =Q7/SUM($Q$4:$Q$806) -> 0.015538944 | S7: =R7+S6 -> 0.095719894 | T7: =IF(S7<0.8,"A", IF(S7<0.95,"B","C")) -> A | V7: ВАЛИДОЛ 60МГ. №10 ТАБ. ПОДЪЯЗЫЧ. /ФАРМСТАНДАРТ/ | W7: A
A8: 44774 | B8: КЛОПИДОГРЕЛ-СЗ 75МГ. №28 ТАБ. П/П/О /СЕВЕРНАЯ ЗВЕЗДА/ | C8: 1 | F8: L-ТИРОКСИН 150МКГ. №100 ТАБ. /БЕРЛИН ХЕМИ/ | K8: 1 | L8: 1 | O8: БОРНАЯ К-ТА 10Г. ДЕЗ.СР-ВО ПОР. (НДС 20%) | P8: 22 | Q8: =(P8/5)*30 -> 132 | R8: =Q8/SUM($Q$4:$Q$806) -> 0.013674271 | S8: =R8+S7 -> 0.10939416 | T8: =IF(S8<0.8,"A", IF(S8<0.95,"B","C")) -> A | V8: БОРНАЯ К-ТА 10Г. ДЕЗ.СР-ВО ПОР. (НДС 20%) | W8: A
A9: 44774 | B9: КО-ВАМЛОСЕТ 5МГ.+160МГ.+12,5МГ. №30 ТАБ. П/П/О | C9: 1 | F9: L-ТИРОКСИН 50МКГ. №50 ТАБ. /БЕРЛИН ХЕМИ/ | G9: 1 | J9: 1 | L9: 2 | O9: ГЕМАТОГЕН РУССКИЙ ДЕТСКИЙ 40Г. ПЛИТКА /ФАРМ-ПРО/ | P9: 17 | Q9: =(P9/5)*30 -> 102 | R9: =Q9/SUM($Q$4:$Q$806) -> 0.010566482 | S9: =R9+S8 -> 0.11996065 | T9: =IF(S9<0.8,"A", IF(S9<0.95,"B","C")) -> A | V9: ГЕМАТОГЕН РУССКИЙ ДЕТСКИЙ 40Г. ПЛИТКА /ФАРМ-ПРО/ | W9: A
A10: 44774 | B10: АТОРВАСТАТИН-СЗ 20МГ. №60 ТАБ. П/П/О /СЕВЕРНАЯ ЗВЕЗДА/ | C10: 1 | F10: L-ТИРОКСИН 75МКГ. №100 ТАБ. /БЕРЛИН ХЕМИ/ | G10: 2 | J10: 1 | L10: 3 | O10: КОРВАЛОЛ 25МЛ. КАПЛИ Д/ПРИЕМА ВНУТРЬ ФЛ. И/У /ФАРМСТАНДАРТ ЛЕКСРЕДСТВА/ | P10: 14 | Q10: =(P10/5)*30 -> 84 | R10: =Q10/SUM($Q$4:$Q$806) -> 0.0087018086 | S10: =R10+S9 -> 0.12866246 | T10: =IF(S10<0.8,"A", IF(S10<0.95,"B","C")) -> A | V10: КОРВАЛОЛ 25МЛ. КАПЛИ Д/ПРИЕМА ВНУТРЬ ФЛ. И/У /ФАРМСТАНДАРТ ЛЕКСРЕДСТВА/ | W10: A
A11: 44774 | B11: АТОРВАСТАТИН-СЗ 40МГ. №30 ТАБ. П/П/О /СЕВЕРНАЯ ЗВЕЗДА/ | C11: 1 | F11: NF ВАТА ХИРУРГ. СТЕР. 100Г. /НЬЮФАРМ/ | G11: 1 | L11: 1 | O11: ЛЕЙКОПЛАСТЫРЬ БАКТЕР. 4Х10 №1 /ВЕРОФАРМ/ | P11: 14 | Q11: =(P11/5)*30 -> 84 | R11: =Q11/SUM($Q$4:$Q$806) -> 0.0087018086 | S11: =R11+S10 -> 0.13736426 | T11: =IF(S11<0.8,"A", IF(S11<0.95,"B","C")) -> A | V11: ЛЕЙКОПЛАСТЫРЬ БАКТЕР. 4Х10 №1 /ВЕРОФАРМ/ | W11: A
A12: 44774 | B12: КСИМЕЛИН ЭКСТРА 84МКГ/ДОЗА+70МКГ/ДОЗА 10МЛ. №1 НАЗАЛ.СПРЕЙ ДОЗИР. ФЛ. | C12: 1 | F12: АДЖИСЕПТ МЕД+ЛИМОН №24 ТАБ. Д/РАСС. | I12: 1 | L12: 1 | O12: ЛЕЙКОПЛАСТЫРЬ БАКТЕР. 6X10 №1 /ВЕРОФАРМ/ | P12: 13 | Q12: =(P12/5)*30 -> 78 | R12: =Q12/SUM($Q$4:$Q$806) -> 0.0080802508 | S12: =R12+S11 -> 0.14544451 | T12: =IF(S12<0.8,"A", IF(S12<0.95,"B","C")) -> A | V12: ЛЕЙКОПЛАСТЫРЬ БАКТЕР. 6X10 №1 /ВЕРОФАРМ/ | W12: A
A13: 44774 | B13: NF ВАТА ХИРУРГ. СТЕР. 100Г. /НЬЮФАРМ/ | C13: 1 | F13: АДЖИСЕПТ МЕНТОЛ+ЭВКАЛИПТ №24 ТАБ. Д/РАСС. | H13: 1 | L13: 1 | O13: МЕНОВАЗИН 40МЛ. №1 СПИРТ. Р-Р Д/НАРУЖ.ПРИМ. ФЛ. /САМАРАМЕДПРОМ/ | P13: 13 | Q13: =(P13/5)*30 -> 78 | R13: =Q13/SUM($Q$4:$Q$806) -> 0.0080802508 | S13: =R13+S12 -> 0.15352477 | T13: =IF(S13<0.8,"A", IF(S13<0.95,"B","C")) -> A | V13: МЕНОВАЗИН 40МЛ. №1 СПИРТ. Р-Р Д/НАРУЖ.ПРИМ. ФЛ. /САМАРАМЕДПРОМ/ | W13: A
A14: 44774 | B14: СТОПСЕПТ ПЛЮС 90% 100МЛ. ДЕЗ.СР-ВО ФЛ. | C14: 1 | F14: АЕВИТ 200МГ. №20 КАПС. (БАД) /МЕЛИГЕН/ | I14: 1 | L14: 1 | O14: ПЕРЕКИСЬ ВОДОРОДА 3% 100МЛ. №1 Р-Р ДЕЗ.СР-ВО ФЛ. (НДС 20%) | P14: 13 | Q14: =(P14/5)*30 -> 78 | R14: =Q14/SUM($Q$4:$Q$806) -> 0.0080802508 | S14: =R14+S13 -> 0.16160502 | T14: =IF(S14<0.8,"A", IF(S14<0.95,"B","C")) -> A | V14: ПЕРЕКИСЬ ВОДОРОДА 3% 100МЛ. №1 Р-Р ДЕЗ.СР-ВО ФЛ. (НДС 20%) | W14: A
A15: 44774 | B15: ПАСКАЛЬ ШПРИЦ 3-Х КОМП. 2МЛ. С ИГЛОЙ 23G 0,6Х30ММ. №10 [PASCAL] | C15: 1 | F15: АЗАРГА 10МГ/МЛ.+5МГ/МЛ. 5МЛ. №1 ГЛ.КАПЛИ ФЛ./КАП. | G15: 1 | H15: 1 | L15: 2 | O15: РАУНАТИН 2МГ. №50 ТАБ. П/О /ЗДОРОВЬЕ/ | P15: 13 | Q15: =(P15/5)*30 -> 78 | R15: =Q15/SUM($Q$4:$Q$806) -> 0.0080802508 | S15: =R15+S14 -> 0.16968527 | T15: =IF(S15<0.8,"A", IF(S15<0.95,"B","C")) -> A | V15: РАУНАТИН 2МГ. №50 ТАБ. П/О /ЗДОРОВЬЕ/ | W15: A
A16: 44774 | B16: ПАСКАЛЬ ШПРИЦ 3-Х КОМП. 2МЛ. С ИГЛОЙ 23G 0,6Х30ММ. №10 [PASCAL] | C16: 1 | F16: АЗИТРОМИЦИН 500МГ. №3 КАПС. /ПРОИЗВОДСТВО МЕДИКАМЕНТОВ/ ПроМед/ | I16: 2 | L16: 2 | O16: Карта LOYALITY 0,01Р | P16: 12 | Q16: =(P16/5)*30 -> 72 | R16: =Q16/SUM($Q$4:$Q$806) -> 0.007458693 | S16: =R16+S15 -> 0.17714396 | T16: =IF(S16<0.8,"A", IF(S16<0.95,"B","C")) -> A | V16: Карта LOYALITY 0,01Р | W16: A
A17: 44774 | B17: КЛОТРИМАЗОЛ 1% 20Г. КРЕМ Д/НАРУЖ.ПРИМ. ТУБА /ХИПЕРИОН/РУМЫНИЯ/ | C17: 1 | F17: АЙДИ ПРОТЕКТ ПЕЛЕНКИ ОДНОР. ВПИТ. 60Х90 №10 [ID] | I17: 1 | L17: 1 | O17: КОНТЕЙНЕР Д/СБОРА БИОМАТЕРИАЛА 100МЛ. СТЕР. (БАНКА) | P17: 11 | Q17: =(P17/5)*30 -> 66 | R17: =Q17/SUM($Q$4:$Q$806) -> 0.0068371353 | S17: =R17+S16 -> 0.1839811 | T17: =IF(S17<0.8,"A", IF(S17<0.95,"B","C")) -> A | V17: КОНТЕЙНЕР Д/СБОРА БИОМАТЕРИАЛА 100МЛ. СТЕР. (БАНКА) | W17: A
A18: 44774 | B18: РИНОНОРМ-ТЕВА 0,1% 140МКГ/ДОЗА 20МЛ. НАЗАЛ.СПРЕЙ ФЛ. /ТЕВА/ | C18: 1 | F18: АКВА МАРИС НОРМ ИНТЕНСИВ. ПРОМЫВАНИЕ 150МЛ. НАЗАЛ.СПРЕЙ | J18: 1 | L18: 1 | O18: ОМЕПРАЗОЛ 20МГ. №30 КАПС. /ПРОИЗВОДСТВО МЕДИКАМЕНТОВ/ | P18: 11 | Q18: =(P18/5)*30 -> 66 | R18: =Q18/SUM($Q$4:$Q$806) -> 0.0068371353 | S18: =R18+S17 -> 0.19081823 | T18: =IF(S18<0.8,"A", IF(S18<0.95,"B","C")) -> A | V18: ОМЕПРАЗОЛ 20МГ. №30 КАПС. /ПРОИЗВОДСТВО МЕДИКАМЕНТОВ/ | W18: A
A19: 44774 | B19: РИНОНОРМ-ТЕВА 0,1% 140МКГ/ДОЗА 20МЛ. НАЗАЛ.СПРЕЙ ФЛ. /ТЕВА/ | C19: 1 | F19: АКВА ЭЙР МОРЕ 50МЛ. НАЗАЛ.СПРЕЙ ФЛ. | K19: 1 | L19: 1 | O19: ТАУФОН 4% 10МЛ. №1 ГЛ.КАПЛИ ФЛ./КАП. /ОТИСИФАРМ/ФАРМСТАНДАРТ/ | P19: 11 | Q19: =(P19/5)*30 -> 66 | R19: =Q19/SUM($Q$4:$Q$806) -> 0.0068371353 | S19: =R19+S18 -> 0.19765537 | T19: =IF(S19<0.8,"A", IF(S19<0.95,"B","C")) -> A | V19: ТАУФОН 4% 10МЛ. №1 ГЛ.КАПЛИ ФЛ./КАП. /ОТИСИФАРМ/ФАРМСТАНДАРТ/ | W19: A
A20: 44774 | B20: ДЮФАЛАК 667МГ/МЛ. 500МЛ. СИРОП ФЛ. +МЕРН.СТАКАН /ЭББОТТ/СОЛВЕЙ/ | C20: 1 | F20: АКВАДЕТРИМ 15000МЕ/МЛ. 10МЛ. КАПЛИ Д/ПРИЕМА ВНУТРЬ ФЛ./КАП. (ВИТАМИН Д3 ВОДН.Р-Р) /МЕДАНА/ | K20: 1 | L20: 1 | O20: ПЕНТАЛГИН №24 ТАБ. П/П/О /ОТИСИФАРМ/ | P20: 10 | Q20: =(P20/5)*30 -> 60 | R20: =Q20/SUM($Q$4:$Q$806) -> 0.0062155775 | S20: =R20+S19 -> 0.20387094 | T20: =IF(S20<0.8,"A", IF(S20<0.95,"B","C")) -> A | V20: ПЕНТАЛГИН №24 ТАБ. П/П/О /ОТИСИФАРМ/ | W20: A
A21: 44774 | B21: ГЕЛАДРИНК ФОРТЕ ПОР. Д/ПРИЕМА ВНУТРЬ АПЕЛЬСИН 420Г. БАНКА | C21: 1 | F21: АКВАЛОР ЭКСТРА ФОРТЕ 150МЛ. АЛОЭ+РОМАШКА НАЗАЛ.СПРЕЙ | H21: 1 | L21: 1 | O21: УГОЛЬ АКТИВИРОВАННЫЙ 250МГ. №50 ТАБ. /ФАРМСТАНДАРТ ЛЕКСРЕДСТВА/ | P21: 10 | Q21: =(P21/5)*30 -> 60 | R21: =Q21/SUM($Q$4:$Q$806) -> 0.0062155775 | S21: =R21+S20 -> 0.21008652 | T21: =IF(S21<0.8,"A", IF(S21<0.95,"B","C")) -> A | V21: УГОЛЬ АКТИВИРОВАННЫЙ 250МГ. №50 ТАБ. /ФАРМСТАНДАРТ ЛЕКСРЕДСТВА/ | W21: A
A22: 44774 | B22: ПИРАЦЕТАМ 200МГ. №60 ТАБ. П/П/О /ОБНОВЛЕНИЕ/ | C22: 1 | F22: АККУ-ЧЕК ТЕСТ-ПОЛОСКИ ПЕРФОРМА №100 (50Х2) [ACCU-CHEK] | I22: 0.5 | L22: 0.5 | O22: ЦЕФТРИАКСОН 1Г. №1 ПОР. Д/Р-РА Д/В/В,В/М ФЛ. /ПРОМОМЕД/БИОХИМИК/ | P22: 10 | Q22: =(P22/5)*30 -> 60 | R22: =Q22/SUM($Q$4:$Q$806) -> 0.0062155775 | S22: =R22+S21 -> 0.2163021 | T22: =IF(S22<0.8,"A", IF(S22<0.95,"B","C")) -> A | V22: ЦЕФТРИАКСОН 1Г. №1 ПОР. Д/Р-РА Д/В/В,В/М ФЛ. /ПРОМОМЕД/БИОХИМИК/ | W22: A
A23: 44774 | B23: МАГНЕЛИС В6 №120 ТАБ. П/О | C23: 1 | F23: АКРИДЕРМ 0,05% 30Г. №1 КРЕМ Д/НАРУЖ.ПРИМ. ТУБА /АКРИХИН/ | H23: 1 | L23: 1 | O23: КОНКОР КОР 2,5МГ. №30 ТАБ. П/П/О /МЕРК/ | P23: 9 | Q23: =(P23/5)*30 -> 54 | R23: =Q23/SUM($Q$4:$Q$806) -> 0.0055940198 | S23: =R23+S22 -> 0.22189612 | T23: =IF(S23<0.8,"A", IF(S23<0.95,"B","C")) -> A | V23: КОНКОР КОР 2,5МГ. №30 ТАБ. П/П/О /МЕРК/ | W23: A
A24: 44774 | B24: МЕЗИМ-ФОРТЕ №80 ТАБ. П/О /БЕРЛИН-ХЕМИ/ | C24: 1 | F24: АКРИДЕРМ 0,05% 30Г. №1 МАЗЬ Д/НАРУЖ.ПРИМ. ТУБА /АКРИХИН/ | I24: 1 | L24: 1 | O24: ЛОПЕРАМИД-АКРИХИН 2МГ. №20 КАПС. /АКРИХИН/ | P24: 9 | Q24: =(P24/5)*30 -> 54 | R24: =Q24/SUM($Q$4:$Q$806) -> 0.0055940198 | S24: =R24+S23 -> 0.22749014 | T24: =IF(S24<0.8,"A", IF(S24<0.95,"B","C")) -> A | V24: ЛОПЕРАМИД-АКРИХИН 2МГ. №20 КАПС. /АКРИХИН/ | W24: A
A25: 44774 | B25: КАЛЬЦИЙ Д3 НИКОМЕД 500МГ.+200МЕ №60 КЛУБНИКА+АРБУЗ ТАБ.ЖЕВ. | C25: 1 | F25: АКРИДЕРМ ГК 0,05%+0,1%+1% 30Г. №1 КРЕМ Д/НАРУЖ.ПРИМ. ТУБА /АКРИХИН/ | K25: 1 | L25: 1 | O25: ОМЕЗ 20МГ. №30 КАПС. /Д-Р РЕДДИ/ | P25: 9 | Q25: =(P25/5)*30 -> 54 | R25: =Q25/SUM($Q$4:$Q$806) -> 0.0055940198 | S25: =R25+S24 -> 0.23308416 | T25: =IF(S25<0.8,"A", IF(S25<0.95,"B","C")) -> A | V25: ОМЕЗ 20МГ. №30 КАПС. /Д-Р РЕДДИ/ | W25: A
A26: 44774 | B26: ЭКСПРЕСС-ТЕСТ НА А/ТЕЛА COVID-19 LGG/LGM | C26: 2 | F26: АКТОВЕГИН 40МГ/МЛ. 2МЛ. №25 Р-Р Д/ИН. АМП. | K26: 0.2 | L26: 0.2 | O26: ЦЕФТРИАКСОН 1Г. №1 ПОР. Д/Р-РА Д/В/В,В/М ФЛ. /БИОСИНТЕЗ/ | P26: 9 | Q26: =(P26/5)*30 -> 54 | R26: =Q26/SUM($Q$4:$Q$806) -> 0.0055940198 | S26: =R26+S25 -> 0.23867818 | T26: =IF(S26<0.8,"A", IF(S26<0.95,"B","C")) -> A | V26: ЦЕФТРИАКСОН 1Г. №1 ПОР. Д/Р-РА Д/В/В,В/М ФЛ. /БИОСИНТЕЗ/ | W26: A
A27: 44774 | B27: БОБС ЛЕДЕНЦЫ Д/ГОРЛА 35Г. ЭКСТРА МЕНТОЛ №10 | C27: 1 | F27: АКТОВЕГИН 40МГ/МЛ. 5МЛ. №5 Р-Р Д/ИН. АМП. | J27: 1 | L27: 1 | O27: АСЕПТИКА САЛФЕТКА СПИРТОВАЯ 60Х100 №20 | P27: 8 | Q27: =(P27/5)*30 -> 48 | R27: =Q27/SUM($Q$4:$Q$806) -> 0.004972462 | S27: =R27+S26 -> 0.24365064 | T27: =IF(S27<0.8,"A", IF(S27<0.95,"B","C")) -> A | V27: АСЕПТИКА САЛФЕТКА СПИРТОВАЯ 60Х100 №20 | W27: A
A28: 44774 | B28: ЦИТРАМОН П №10 ТАБ. /ФАРМСТАНДАРТ/ | C28: 1 | F28: АКУЛИЙ ЖИР ГЕЛЬ-БАЛЬЗАМ Д/ТЕЛА ОКОПНИК+САБЕЛЬНИК 125МЛ. | I28: 1 | L28: 1 | O28: ВАЛЕРИАНЫ НАСТОЙКА 25МЛ. ФЛ. /ГИППОКРАТ/ | P28: 8 | Q28: =(P28/5)*30 -> 48 | R28: =Q28/SUM($Q$4:$Q$806) -> 0.004972462 | S28: =R28+S27 -> 0.2486231 | T28: =IF(S28<0.8,"A", IF(S28<0.95,"B","C")) -> A | V28: ВАЛЕРИАНЫ НАСТОЙКА 25МЛ. ФЛ. /ГИППОКРАТ/ | W28: A
A29: 44774 | B29: ЦИТРАМОН П №10 ТАБ. /ФАРМСТАНДАРТ/ | C29: 1 | F29: АЛЕРАНА ВИТАМИННО-МИНЕРАЛЬНЫЙ КОМПЛЕКС ДЕНЬ-НОЧЬ №60 ТАБ. [ALERANA] | I29: 1 | L29: 1 | O29: МАСКА МЕД. ТРЕХСЛОЙНАЯ (3-Х) НА РЕЗИНКЕ №5 | P29: 8 | Q29: =(P29/5)*30 -> 48 | R29: =Q29/SUM($Q$4:$Q$806) -> 0.004972462 | S29: =R29+S28 -> 0.25359556 | T29: =IF(S29<0.8,"A", IF(S29<0.95,"B","C")) -> A | V29: МАСКА МЕД. ТРЕХСЛОЙНАЯ (3-Х) НА РЕЗИНКЕ №5 | W29: A
A30: 44774 | B30: ЦИТРАМОН П №10 ТАБ. /ФАРМСТАНДАРТ/ | C30: 1 | F30: АЛЛАПИНИН 25МГ. №30 ТАБ. /ВИЛАР/ | H30: 1 | L30: 1 | O30: ПАНКРЕАТИН 25ЕД №60 ТАБ.КШ/РАСТВ. П/О БАНКА /БИОСИНТЕЗ/ | P30: 7 | Q30: =(P30/5)*30 -> 42 | R30: =Q30/SUM($Q$4:$Q$806) -> 0.0043509043 | S30: =R30+S29 -> 0.25794647 | T30: =IF(S30<0.8,"A", IF(S30<0.95,"B","C")) -> A | V30: ПАНКРЕАТИН 25ЕД №60 ТАБ.КШ/РАСТВ. П/О БАНКА /БИОСИНТЕЗ/ | W30: A
A31: 44774 | B31: ТИЗИН КЛАССИК 0,1% 10МЛ. НАЗАЛ.СПРЕЙ ФЛ. /ДЖОНСОН/ | C31: 1 | F31: АЛЛЕРВЭЙ 5МГ. №10 ТАБ. П/О | I31: 1 | L31: 1 | O31: ПУСТЫРНИКА НАСТОЙКА 25МЛ. ФЛ. /ГИППОКРАТ/ | P31: 7 | Q31: =(P31/5)*30 -> 42 | R31: =Q31/SUM($Q$4:$Q$806) -> 0.0043509043 | S31: =R31+S30 -> 0.26229737 | T31: =IF(S31<0.8,"A", IF(S31<0.95,"B","C")) -> A | V31: ПУСТЫРНИКА НАСТОЙКА 25МЛ. ФЛ. /ГИППОКРАТ/ | W31: A
A32: 44774 | B32: ЛАКОМКА ПОМАДА ГИГИЕН. ЯГОДНЫЙ МИКС 2,8Г. /АВАНТА/ | C32: 1 | F32: АЛЛОХОЛ №50 ТАБ. П/О /ФАРМСТАНДАРТ/ | H32: 1 | L32: 1 | O32: ТАУРИН 4% 10МЛ. ГЛ.КАПЛИ ФЛ./КАП. /СЛАВЯНСКАЯ АПТЕКА/ | P32: 7 | Q32: =(P32/5)*30 -> 42 | R32: =Q32/SUM($Q$4:$Q$806) -> 0.0043509043 | S32: =R32+S31 -> 0.26664828 | T32: =IF(S32<0.8,"A", IF(S32<0.95,"B","C")) -> A | V32: ТАУРИН 4% 10МЛ. ГЛ.КАПЛИ ФЛ./КАП. /СЛАВЯНСКАЯ АПТЕКА/ | W32: A
A33: 44774 | B33: ОМЕЗ 20МГ. №30 КАПС. /Д-Р РЕДДИ/ | C33: 1 | F33: АЛМАГЕЛЬ А 170МЛ. №1 СУСП. Д/ПРИЕМА ВНУТРЬ ФЛ. /БАЛКАН ФАРМА-ТРОЯН/ | H33: 1 | L33: 1 | O33: ФЕРРОГЕМАТОГЕН 50Г. ПАСТИЛКА ЖЕВ. (ПЛИТКА) | P33: 7 | Q33: =(P33/5)*30 -> 42 | R33: =Q33/SUM($Q$4:$Q$806) -> 0.0043509043 | S33: =R33+S32 -> 0.27099918 | T33: =IF(S33<0.8,"A", IF(S33<0.95,"B","C")) -> A | V33: ФЕРРОГЕМАТОГЕН 50Г. ПАСТИЛКА ЖЕВ. (ПЛИТКА) | W33: A
A34: 44774 | B34: ЭВКАЛИПТ М №24 ПАСТИЛКИ | C34: 2 | F34: АЛЬФА НОРМИКС 200МГ. №12 ТАБ. П/П/О | K34: 1 | L34: 1 | O34: ХЕЛП БИНТ СТЕР. 7МХ14СМ И/У [HELP] | P34: 7 | Q34: =(P34/5)*30 -> 42 | R34: =Q34/SUM($Q$4:$Q$806) -> 0.0043509043 | S34: =R34+S33 -> 0.27535009 | T34: =IF(S34<0.8,"A", IF(S34<0.95,"B","C")) -> A | V34: ХЕЛП БИНТ СТЕР. 7МХ14СМ И/У [HELP] | W34: A
A35: 44774 | B35: АЗАРГА 10МГ/МЛ.+5МГ/МЛ. 5МЛ. №1 ГЛ.КАПЛИ ФЛ./КАП. | C35: 1 | F35: АЛЬФА НОРМИКС 200МГ. №28 ТАБ. П/П/О | H35: 1 | L35: 1 | O35: ЭСВИЦИН СР-ВО П/ОБЛЫСЕНИЯ ЛОСЬОН-ТОНИК 250МЛ. ФЛ. /ВИО-ФАРМ/ | P35: 7 | Q35: =(P35/5)*30 -> 42 | R35: =Q35/SUM($Q$4:$Q$806) -> 0.0043509043 | S35: =R35+S34 -> 0.27970099 | T35: =IF(S35<0.8,"A", IF(S35<0.95,"B","C")) -> A | V35: ЭСВИЦИН СР-ВО П/ОБЛЫСЕНИЯ ЛОСЬОН-ТОНИК 250МЛ. ФЛ. /ВИО-ФАРМ/ | W35: A
A36: 44774 | B36: ТРАВАТАН 0,004% 2,5МЛ. №3 ГЛ.КАПЛИ ФЛ./КАП. | C36: 1 | F36: АЛЬФА ТОКОФЕРОЛА АЦЕТАТ 200МГ. №30 КАПС. (ВИТАМИН Е) /МИНСКИНТЕРКАПС/ | J36: 1 | L36: 1 | O36: АСКОРБИНКА ЛУНТИК ВИТ.С №10 ТАБ. (30Г.) /ФАРМ-ПРО/ТИГОДА-ФАРМ/ | P36: 6 | Q36: =(P36/5)*30 -> 36 | R36: =Q36/SUM($Q$4:$Q$806) -> 0.0037293465 | S36: =R36+S35 -> 0.28343034 | T36: =IF(S36<0.8,"A", IF(S36<0.95,"B","C")) -> A | V36: АСКОРБИНКА ЛУНТИК ВИТ.С №10 ТАБ. (30Г.) /ФАРМ-ПРО/ТИГОДА-ФАРМ/ | W36: A
A37: 44774 | B37: ЙОДА 5% 10МЛ. СПИРТ. Р-Р ФЛ. /ЯРОСЛАВСКАЯ ФФ/ | C37: 1 | F37: АЛЬФАГАН Р 0,15% 5МЛ. ГЛ.КАПЛИ ФЛ./КАП. | H37: 1 | L37: 1 | O37: АСПАРКАМ №60 ТАБ. /ФАРМАПОЛ-ВОЛГА/ | P37: 6 | Q37: =(P37/5)*30 -> 36 | R37: =Q37/SUM($Q$4:$Q$806) -> 0.0037293465 | S37: =R37+S36 -> 0.28715968 | T37: =IF(S37<0.8,"A", IF(S37<0.95,"B","C")) -> A | V37: АСПАРКАМ №60 ТАБ. /ФАРМАПОЛ-ВОЛГА/ | W37: A
A38: 44774 | B38: ОМЕПРАЗОЛ 20МГ. №30 КАПС. /ПРОИЗВОДСТВО МЕДИКАМЕНТОВ/ | C38: 1 | F38: АЛЬФАПЛАСТИК ТРУБКА РЕКТАЛЬНАЯ ГАЗООТВОДНАЯ Д/НОВОРОЖД. №16 | I38: 1 | L38: 1 | O38: КЕТОРОЛ ЭКСПРЕСС 10МГ. №20 ТАБ. ДИСПЕРГ. /Д-Р РЕДДИС/ | P38: 6 | Q38: =(P38/5)*30 -> 36 | R38: =Q38/SUM($Q$4:$Q$806) -> 0.0037293465 | S38: =R38+S37 -> 0.29088903 | T38: =IF(S38<0.8,"A", IF(S38<0.95,"B","C")) -> A | V38: КЕТОРОЛ ЭКСПРЕСС 10МГ. №20 ТАБ. ДИСПЕРГ. /Д-Р РЕДДИС/ | W38: A
A39: 44774 | B39: ОМЕПРАЗОЛ 20МГ. №30 КАПС. /ПРОИЗВОДСТВО МЕДИКАМЕНТОВ/ | C39: 1 | F39: АМБРОКСОЛ-АЛСИ 30МГ. №30 ТАБ. /АЛСИ/ | J39: 1 | L39: 1 | O39: ПАСКАЛЬ ШПРИЦ 3-Х КОМП. 3МЛ. С ИГЛОЙ 22G 0,7Х40ММ. №10 [PASCAL] | P39: 6 | Q39: =(P39/5)*30 -> 36 | R39: =Q39/SUM($Q$4:$Q$806) -> 0.0037293465 | S39: =R39+S38 -> 0.29461838 | T39: =IF(S39<0.8,"A", IF(S39<0.95,"B","C")) -> A | V39: ПАСКАЛЬ ШПРИЦ 3-Х КОМП. 3МЛ. С ИГЛОЙ 22G 0,7Х40ММ. №10 [PASCAL] | W39: A
A40: 44774 | B40: ОМЕПРАЗОЛ 20МГ. №30 КАПС. /ПРОИЗВОДСТВО МЕДИКАМЕНТОВ/ | C40: 1 | F40: АМЕЛИЯ ВАТА МЕД. ХИРУРГ. Н/СТЕР. 25Г. | I40: 1 | L40: 1 | O40: ПУСТЫРНИКА ЭКСТРАКТ 14МГ. №50 ТАБ. /ФАРМСТАНДАРТ/ | P40: 6 | Q40: =(P40/5)*30 -> 36 | R40: =Q40/SUM($Q$4:$Q$806) -> 0.0037293465 | S40: =R40+S39 -> 0.29834772 | T40: =IF(S40<0.8,"A", IF(S40<0.95,"B","C")) -> A | V40: ПУСТЫРНИКА ЭКСТРАКТ 14МГ. №50 ТАБ. /ФАРМСТАНДАРТ/ | W40: A
...

Sheet ИТОГ
A3: Названия | B3: Количество | C3: Сумма продаж | D3: Месячная рент. | E3: Итог
A4: ЛЕЙКОПЛАСТЫРЬ БАКТЕР. 2,5Х7,2 №1 /ВЕРОФАРМ/ | B4: A | C4: B | D4: A | E4: =B4&C4&D4 -> ABA
A5: НАФТИЗИН 0,1% 15МЛ. НАЗАЛ.КАПЛИ ФЛ./КАП. /СЛАВЯНСКАЯ АПТЕКА/ | B5: A | C5: B | D5: A | E5: =B5&C5&D5 -> ABA
A6: ПАКЕТ | B6: A | C6: C | D6: A | E6: =B6&C6&D6 -> ACA
A7: ВАЛИДОЛ 60МГ. №10 ТАБ. ПОДЪЯЗЫЧ. /ФАРМСТАНДАРТ/ | B7: A | C7: A | D7: A | E7: =B7&C7&D7 -> AAA
A8: БОРНАЯ К-ТА 10Г. ДЕЗ.СР-ВО ПОР. (НДС 20%) | B8: A | C8: B | D8: A | E8: =B8&C8&D8 -> ABA
A9: ГЕМАТОГЕН РУССКИЙ ДЕТСКИЙ 40Г. ПЛИТКА /ФАРМ-ПРО/ | B9: A | C9: B | D9: A | E9: =B9&C9&D9 -> ABA
A10: КОРВАЛОЛ 25МЛ. КАПЛИ Д/ПРИЕМА ВНУТРЬ ФЛ. И/У /ФАРМСТАНДАРТ ЛЕКСРЕДСТВА/ | B10: A | C10: A | D10: A | E10: =B10&C10&D10 -> AAA
A11: ЛЕЙКОПЛАСТЫРЬ БАКТЕР. 4Х10 №1 /ВЕРОФАРМ/ | B11: A | C11: C | D11: A | E11: =B11&C11&D11 -> ACA
A12: ЛЕЙКОПЛАСТЫРЬ БАКТЕР. 6X10 №1 /ВЕРОФАРМ/ | B12: A | C12: C | D12: A | E12: =B12&C12&D12 -> ACA
A13: МЕНОВАЗИН 40МЛ. №1 СПИРТ. Р-Р Д/НАРУЖ.ПРИМ. ФЛ. /САМАРАМЕДПРОМ/ | B13: A | C13: A | D13: A | E13: =B13&C13&D13 -> AAA
A14: ПЕРЕКИСЬ ВОДОРОДА 3% 100МЛ. №1 Р-Р ДЕЗ.СР-ВО ФЛ. (НДС 20%) | B14: A | C14: B | D14: A | E14: =B14&C14&D14 -> ABA
A15: РАУНАТИН 2МГ. №50 ТАБ. П/О /ЗДОРОВЬЕ/ | B15: A | C15: A | D15: A | E15: =B15&C15&D15 -> AAA
... A806: ХАРТМАНН КОСМОПОР Е ПОВЯЗКА 7,2Х5СМ №50 П/ОПЕР. САМОКЛ. СТЕР. /АРТ.9008705/ [HARTMANN COSMOPOR] | B806: C | C806: C | D806: C | E806: =B806&C806&D806 -> CCC
